<?xml version="1.0"?>
<robot name="Cat"><link name="link1"><inertial><origin xyz="0.000000 1.996537 3.568627" rpy="-0.0400 0.0000 0.0000"/><mass value="17"/><inertia ixx="109.0719" ixy="0" ixz="0" iyy="13.3345" iyz="0" izz="118.7374"/></inertial><collision><origin xyz="0.000000 0.000000 3.333333" rpy="0.0000 0.0000 0.0000"/><geometry><mesh filename="Prism.obj"/></geometry></collision><collision><origin xyz="-1.000000 -0.000000 3.666667" rpy="-3.1416 0.0000 0.0000"/><geometry><mesh filename="Prism.obj"/></geometry></collision><collision><origin xyz="1.000000 0.000000 3.666667" rpy="3.1416 0.0000 0.0000"/><geometry><mesh filename="Prism.obj"/></geometry></collision><collision><origin xyz="1.000000 1.414214 3.666667" rpy="3.1416 0.0000 0.0000"/><geometry><mesh filename="Prism.obj"/></geometry></collision><collision><origin xyz="0.000000 1.414214 3.333333" rpy="0.0000 0.0000 0.0000"/><geometry><mesh filename="Prism.obj"/></geometry></collision><collision><origin xyz="-1.000000 1.414214 3.666667" rpy="-3.1416 0.0000 0.0000"/><geometry><mesh filename="Prism.obj"/></geometry></collision><collision><origin xyz="-1.000000 2.828427 3.666667" rpy="-3.1416 0.0000 0.0000"/><geometry><mesh filename="Prism.obj"/></geometry></collision><collision><origin xyz="1.000000 2.828427 3.666667" rpy="3.1416 0.0000 0.0000"/><geometry><mesh filename="Prism.obj"/></geometry></collision><collision><origin xyz="0.000000 2.828427 3.333333" rpy="0.0000 0.0000 0.0000"/><geometry><mesh filename="Prism.obj"/></geometry></collision><collision><origin xyz="1.000000 4.242640 3.666667" rpy="3.1416 0.0000 0.0000"/><geometry><mesh filename="Prism.obj"/></geometry></collision><collision><origin xyz="-1.000000 4.242640 3.666667" rpy="-3.1416 0.0000 0.0000"/><geometry><mesh filename="Prism.obj"/></geometry></collision><collision><origin xyz="0.000000 4.242640 3.333333" rpy="0.0000 0.0000 0.0000"/><geometry><mesh filename="Prism.obj"/></geometry></collision><collision><origin xyz="0.000000 -1.414214 3.333333" rpy="0.0000 0.0000 0.0000"/><geometry><mesh filename="Prism.obj"/></geometry></collision><collision><origin xyz="-0.666667 -1.414214 4.000000" rpy="0.0000 1.5708 0.0000"/><geometry><mesh filename="Prism.obj"/></geometry></collision><collision><origin xyz="0.666667 -1.414214 4.000000" rpy="-0.0000 -1.5708 0.0000"/><geometry><mesh filename="Prism.obj"/></geometry></collision><collision><origin xyz="0.000000 5.656854 3.333333" rpy="0.0000 0.0000 0.0000"/><geometry><mesh filename="Prism.obj"/></geometry></collision><collision><origin xyz="0.000000 7.071068 3.333333" rpy="0.0000 0.0000 0.0000"/><geometry><mesh filename="Prism.obj"/></geometry></collision></link><link name="link2"><inertial><origin xyz="0.707107 -0.000000 -0.707107" rpy="-3.1416 1.0172 0.0000"/><mass value="2"/><inertia ixx="0.4607" ixy="0" ixz="0" iyy="1.0000" iyz="0" izz="1.2060"/></inertial><collision><origin xyz="0.471405 0.000000 -0.235702" rpy="3.1416 0.7854 -0.0000"/><geometry><mesh filename="Prism.obj"/></geometry></collision><collision><origin xyz="0.942809 -0.000000 -1.178512" rpy="-0.0000 0.7854 -0.0000"/><geometry><mesh filename="Prism.obj"/></geometry></collision></link><joint name="joint1" type="revolute"><origin xyz="1.500000 0.000000 3.500000" rpy="3.1416 0.7854 -0.0000"/><parent link="link1"/><child link="link2"/><axis xyz="1 0 0"/><limit lower="-1.5708" upper="1.5708" effort="100" velocity="10"/></joint><link name="link3"><inertial><origin xyz="1.099944 0.000000 1.021377" rpy="-3.1416 0.7854 0.0000"/><mass value="3"/><inertia ixx="3.0000" ixy="0" ixz="0" iyy="2.7407" iyz="0" izz="0.7407"/></inertial><collision><origin xyz="0.471405 0.000000 0.235702" rpy="-0.0000 -0.7854 0.0000"/><geometry><mesh filename="Prism.obj"/></geometry></collision><collision><origin xyz="0.942809 0.000000 1.178511" rpy="3.1416 -0.7854 0.0000"/><geometry><mesh filename="Prism.obj"/></geometry></collision><collision><origin xyz="1.885618 0.000000 1.649916" rpy="-0.0000 -0.7854 0.0000"/><geometry><mesh filename="Prism.obj"/></geometry></collision></link><joint name="joint2" type="revolute"><origin xyz="1.414214 0.000000 -1.414214" rpy="-0.0000 0.0000 0.0000"/><parent link="link2"/><child link="link3"/><axis xyz="1 0 0"/><limit lower="-1.5708" upper="1.5708" effort="100" velocity="10"/></joint><link name="link4"><inertial><origin xyz="0.707107 -0.000000 -0.707107" rpy="-0.0000 -2.1244 -0.0000"/><mass value="2"/><inertia ixx="0.4607" ixy="0" ixz="0" iyy="1.0000" iyz="0" izz="1.2060"/></inertial><collision><origin xyz="0.471405 0.000000 -0.235702" rpy="0.0000 -2.3562 0.0000"/><geometry><mesh filename="Prism.obj"/></geometry></collision><collision><origin xyz="0.942809 -0.000000 -1.178512" rpy="-3.1416 -2.3562 0.0000"/><geometry><mesh filename="Prism.obj"/></geometry></collision></link><joint name="joint3" type="revolute"><origin xyz="-1.500000 0.000000 3.500000" rpy="-0.0000 2.3562 0.0000"/><parent link="link1"/><child link="link4"/><axis xyz="1 0 0"/><limit lower="-1.5708" upper="1.5708" effort="100" velocity="10"/></joint><link name="link5"><inertial><origin xyz="1.099944 0.000000 1.021377" rpy="-0.0000 -2.3562 -0.0000"/><mass value="3"/><inertia ixx="3.0000" ixy="0" ixz="0" iyy="2.7407" iyz="0" izz="0.7407"/></inertial><collision><origin xyz="0.471405 0.000000 0.235702" rpy="-3.1416 2.3562 -0.0000"/><geometry><mesh filename="Prism.obj"/></geometry></collision><collision><origin xyz="0.942809 0.000000 1.178511" rpy="0.0000 2.3562 -0.0000"/><geometry><mesh filename="Prism.obj"/></geometry></collision><collision><origin xyz="1.885618 0.000000 1.649916" rpy="-3.1416 2.3562 -0.0000"/><geometry><mesh filename="Prism.obj"/></geometry></collision></link><joint name="joint4" type="revolute"><origin xyz="1.414214 0.000000 -1.414214" rpy="-0.0000 0.0000 0.0000"/><parent link="link4"/><child link="link5"/><axis xyz="1 0 0"/><limit lower="-1.5708" upper="1.5708" effort="100" velocity="10"/></joint><link name="link6"><inertial><origin xyz="0.707107 0.000000 -0.707107" rpy="-3.1416 1.0172 0.0000"/><mass value="2"/><inertia ixx="0.4607" ixy="0" ixz="0" iyy="1.0000" iyz="0" izz="1.2060"/></inertial><collision><origin xyz="0.471405 0.000000 -0.235702" rpy="3.1416 0.7854 -0.0000"/><geometry><mesh filename="Prism.obj"/></geometry></collision><collision><origin xyz="0.942809 0.000000 -1.178512" rpy="-0.0000 0.7854 -0.0000"/><geometry><mesh filename="Prism.obj"/></geometry></collision></link><joint name="joint5" type="revolute"><origin xyz="1.500000 4.242640 3.500000" rpy="3.1416 0.7854 -0.0000"/><parent link="link1"/><child link="link6"/><axis xyz="1 0 0"/><limit lower="-1.5708" upper="1.5708" effort="100" velocity="10"/></joint><link name="link7"><inertial><origin xyz="1.099944 0.000000 1.021377" rpy="-3.1416 0.7854 0.0000"/><mass value="3"/><inertia ixx="3.0000" ixy="0" ixz="0" iyy="2.7407" iyz="0" izz="0.7407"/></inertial><collision><origin xyz="0.471405 0.000000 0.235702" rpy="-0.0000 -0.7854 0.0000"/><geometry><mesh filename="Prism.obj"/></geometry></collision><collision><origin xyz="0.942809 0.000000 1.178511" rpy="3.1416 -0.7854 0.0000"/><geometry><mesh filename="Prism.obj"/></geometry></collision><collision><origin xyz="1.885618 0.000000 1.649916" rpy="-0.0000 -0.7854 0.0000"/><geometry><mesh filename="Prism.obj"/></geometry></collision></link><joint name="joint6" type="revolute"><origin xyz="1.414214 0.000000 -1.414214" rpy="-0.0000 0.0000 0.0000"/><parent link="link6"/><child link="link7"/><axis xyz="1 0 0"/><limit lower="-1.5708" upper="1.5708" effort="100" velocity="10"/></joint><link name="link8"><inertial><origin xyz="0.707107 0.000000 -0.707107" rpy="-0.0000 -2.1244 -0.0000"/><mass value="2"/><inertia ixx="0.4607" ixy="0" ixz="0" iyy="1.0000" iyz="0" izz="1.2060"/></inertial><collision><origin xyz="0.471405 0.000000 -0.235702" rpy="0.0000 -2.3562 0.0000"/><geometry><mesh filename="Prism.obj"/></geometry></collision><collision><origin xyz="0.942809 0.000000 -1.178512" rpy="-3.1416 -2.3562 0.0000"/><geometry><mesh filename="Prism.obj"/></geometry></collision></link><joint name="joint7" type="revolute"><origin xyz="-1.500000 4.242640 3.500000" rpy="-0.0000 2.3562 0.0000"/><parent link="link1"/><child link="link8"/><axis xyz="1 0 0"/><limit lower="-1.5708" upper="1.5708" effort="100" velocity="10"/></joint><link name="link9"><inertial><origin xyz="1.099944 0.000000 1.021377" rpy="-0.0000 -2.3562 -0.0000"/><mass value="3"/><inertia ixx="3.0000" ixy="0" ixz="0" iyy="2.7407" iyz="0" izz="0.7407"/></inertial><collision><origin xyz="0.471405 0.000000 0.235702" rpy="-3.1416 2.3562 -0.0000"/><geometry><mesh filename="Prism.obj"/></geometry></collision><collision><origin xyz="0.942809 0.000000 1.178511" rpy="0.0000 2.3562 -0.0000"/><geometry><mesh filename="Prism.obj"/></geometry></collision><collision><origin xyz="1.885618 0.000000 1.649916" rpy="-3.1416 2.3562 -0.0000"/><geometry><mesh filename="Prism.obj"/></geometry></collision></link><joint name="joint8" type="revolute"><origin xyz="1.414214 0.000000 -1.414214" rpy="-0.0000 0.0000 0.0000"/><parent link="link8"/><child link="link9"/><axis xyz="1 0 0"/><limit lower="-1.5708" upper="1.5708" effort="100" velocity="10"/></joint></robot>